Workbook

Sheet Inputs
A1: Bloomberg point-in-time index members
A3: First snapshot date | B3: 42005 | D3: How to use
A4: Months between snapshots | B4: 3 | D4: Type Bloomberg index tickers and a peer group name in D11:E16 (yellow). The filled rows are examples.
D5: Set the first date and spacing in B3:B4, then Bloomberg tab > Refresh Workbook.
D6: Each index gets one member list per snapshot date on the Members tab (dates after today stay blank).
A10: Snapshot | B10: Date | D10: Index | E10: Peer group | F10: Members tab column
A11: 1 | B11: =$B$3 | D11: RLG Index | E11: Russell 1000 Growth | F11: A
A12: 2 | B12: =EDATE(B11,$B$4) | D12: RLV Index | E12: Russell 1000 Value | F12: EO
A13: 3 | B13: =EDATE(B12,$B$4) | F13: KC
A14: 4 | B14: =EDATE(B13,$B$4) | F14: PQ
A15: 5 | B15: =EDATE(B14,$B$4) | F15: VE
A16: 6 | B16: =EDATE(B15,$B$4) | F16: AAS
A17: 7 | B17: =EDATE(B16,$B$4)
A18: 8 | B18: =EDATE(B17,$B$4)
A19: 9 | B19: =EDATE(B18,$B$4)
A20: 10 | B20: =EDATE(B19,$B$4)
A21: 11 | B21: =EDATE(B20,$B$4)
A22: 12 | B22: =EDATE(B21,$B$4)
A23: 13 | B23: =EDATE(B22,$B$4)
A24: 14 | B24: =EDATE(B23,$B$4)
A25: 15 | B25: =EDATE(B24,$B$4)
A26: 16 | B26: =EDATE(B25,$B$4)
A27: 17 | B27: =EDATE(B26,$B$4)
A28: 18 | B28: =EDATE(B27,$B$4)
... A58: 48 | B58: =EDATE(B57,$B$4)

Sheet Members
A1: =Inputs!$D$11 | B1: =Inputs!$E$11 | D1: =Inputs!$D$11 | E1: =Inputs!$E$11 | G1: =Inputs!$D$11 | H1: =Inputs!$E$11 | J1: =Inputs!$D$11 | K1: =Inputs!$E$11 | M1: =Inputs!$D$11 | N1: =Inputs!$E$11 | P1: =Inputs!$D$11 | Q1: =Inputs!$E$11 | S1: =Inputs!$D$11 | T1: =Inputs!$E$11 | V1: =Inputs!$D$11 | W1: =Inputs!$E$11 | Y1: =Inputs!$D$11 | Z1: =Inputs!$E$11 | AB1: =Inputs!$D$11 | AC1: =Inputs!$E$11 | AE1: =Inputs!$D$11 | AF1: =Inputs!$E$11 | AH1: =Inputs!$D$11 | AI1: =Inputs!$E$11 | AK1: =Inputs!$D$11 | AL1: =Inputs!$E$11 | AN1: =Inputs!$D$11 | AO1: =Inputs!$E$11 | AQ1: =Inputs!$D$11 | AR1: =Inputs!$E$11 | AT1: =Inputs!$D$11 | AU1: =Inputs!$E$11 | AW1: =Inputs!$D$11 | AX1: =Inputs!$E$11 | AZ1: =Inputs!$D$11 | BA1: =Inputs!$E$11 | BC1: =Inputs!$D$11 | BD1: =Inputs!$E$11 | BF1: =Inputs!$D$11 | BG1: =Inputs!$E$11 | BI1: =Inputs!$D$11 | BJ1: =Inputs!$E$11 | BL1: =Inputs!$D$11 | BM1: =Inputs!$E$11 | BO1: =Inputs!$D$11 | BP1: =Inputs!$E$11 | BR1: =Inputs!$D$11 | BS1: =Inputs!$E$11 | BU1: =Inputs!$D$11 | BV1: =Inputs!$E$11 | BX1: =Inputs!$D$11 | BY1: =Inputs!$E$11 | CA1: =Inputs!$D$11 | CB1: =Inputs!$E$11 | CD1: =Inputs!$D$11 | CE1: =Inputs!$E$11 | CG1: =Inputs!$D$11 | CH1: =Inputs!$E$11 | CJ1: =Inputs!$D$11 | CK1: =Inputs!$E$11 | CM1: =Inputs!$D$11 | CN1: =Inputs!$E$11 | CP1: =Inputs!$D$11 | CQ1: =Inputs!$E$11 | CS1: =Inputs!$D$11 | CT1: =Inputs!$E$11 | CV1: =Inputs!$D$11 | CW1: =Inputs!$E$11 | CY1: =Inputs!$D$11 | CZ1: =Inputs!$E$11 | DB1: =Inputs!$D$11 | DC1: =Inputs!$E$11 | DE1: =Inputs!$D$11 | DF1: =Inputs!$E$11 | DH1: =Inputs!$D$11 | DI1: =Inputs!$E$11 | DK1: =Inputs!$D$11 | DL1: =Inputs!$E$11 | DN1: =Inputs!$D$11 | DO1: =Inputs!$E$11 | DQ1: =Inputs!$D$11 | DR1: =Inputs!$E$11 | DT1: =Inputs!$D$11 | DU1: =Inputs!$E$11 | DW1: =Inputs!$D$11 | DX1: =Inputs!$E$11 | DZ1: =Inputs!$D$11 | EA1: =Inputs!$E$11 | EC1: =Inputs!$D$11 | ED1: =Inputs!$E$11 | EF1: =Inputs!$D$11 | EG1: =Inputs!$E$11 | EI1: =Inputs!$D$11 | EJ1: =Inputs!$E$11 | EL1: =Inputs!$D$11 | EM1: =Inputs!$E$11 | EO1: =Inputs!$D$12 | EP1: =Inputs!$E$12 | ER1: =Inputs!$D$12 | ES1: =Inputs!$E$12 | EU1: =Inputs!$D$12 | EV1: =Inputs!$E$12 | EX1: =Inputs!$D$12 | EY1: =Inputs!$E$12 | FA1: =Inputs!$D$12 | FB1: =Inputs!$E$12 | FD1: =Inputs!$D$12 | FE1: =Inputs!$E$12 | FG1: =Inputs!$D$12 | FH1: =Inputs!$E$12 | FJ1: =Inputs!$D$12 | FK1: =Inputs!$E$12 | FM1: =Inputs!$D$12 | FN1: =Inputs!$E$12 | FP1: =Inputs!$D$12 | FQ1: =Inputs!$E$12 | FS1: =Inputs!$D$12 | FT1: =Inputs!$E$12 | FV1: =Inputs!$D$12 | FW1: =Inputs!$E$12 | FY1: =Inputs!$D$12 | FZ1: =Inputs!$E$12 | GB1: =Inputs!$D$12 | GC1: =Inputs!$E$12 | GE1: =Inputs!$D$12 | GF1: =Inputs!$E$12 | GH1: =Inputs!$D$12 | GI1: =Inputs!$E$12 | GK1: =Inputs!$D$12 | GL1: =Inputs!$E$12 | GN1: =Inputs!$D$12 | GO1: =Inputs!$E$12 | GQ1: =Inputs!$D$12 | GR1: =Inputs!$E$12 | GT1: =Inputs!$D$12 | GU1: =Inputs!$E$12 | GW1: =Inputs!$D$12 | GX1: =Inputs!$E$12 | GZ1: =Inputs!$D$12 | HA1: =Inputs!$E$12 | HC1: =Inputs!$D$12 | HD1: =Inputs!$E$12 | HF1: =Inputs!$D$12 | HG1: =Inputs!$E$12 | HI1: =Inputs!$D$12 | HJ1: =Inputs!$E$12 | HL1: =Inputs!$D$12 | HM1: =Inputs!$E$12 | HO1: =Inputs!$D$12 | HP1: =Inputs!$E$12 | HR1: =Inputs!$D$12 | HS1: =Inputs!$E$12 | HU1: =Inputs!$D$12 | HV1: =Inputs!$E$12 | HX1: =Inputs!$D$12 | HY1: =Inputs!$E$12 | IA1: =Inputs!$D$12 | IB1: =Inputs!$E$12 | ID1: =Inputs!$D$12 | IE1: =Inputs!$E$12 | IG1: =Inputs!$D$12 | IH1: =Inputs!$E$12 | IJ1: =Inputs!$D$12 | IK1: =Inputs!$E$12 | IM1: =Inputs!$D$12 | IN1: =Inputs!$E$12 | IP1: =Inputs!$D$12 | IQ1: =Inputs!$E$12 | IS1: =Inputs!$D$12 | IT1: =Inputs!$E$12 | IV1: =Inputs!$D$12 | IW1: =Inputs!$E$12 | IY1: =Inputs!$D$12 | IZ1: =Inputs!$E$12 | JB1: =Inputs!$D$12 | JC1: =Inputs!$E$12 | JE1: =Inputs!$D$12 | JF1: =Inputs!$E$12 | JH1: =Inputs!$D$12 | JI1: =Inputs!$E$12 | JK1: =Inputs!$D$12 | JL1: =Inputs!$E$12 | JN1: =Inputs!$D$12 | JO1: =Inputs!$E$12 | JQ1: =Inputs!$D$12 | JR1: =Inputs!$E$12 | JT1: =Inputs!$D$12 | JU1: =Inputs!$E$12 | JW1: =Inputs!$D$12 | JX1: =Inputs!$E$12 | JZ1: =Inputs!$D$12 | KA1: =Inputs!$E$12 | KC1: =Inputs!$D$13 | KD1: =Inputs!$E$13 | KF1: =Inputs!$D$13 | KG1: =Inputs!$E$13 | KI1: =Inputs!$D$13 | KJ1: =Inputs!$E$13 | KL1: =Inputs!$D$13 | KM1: =Inputs!$E$13 | KO1: =Inputs!$D$13 | KP1: =Inputs!$E$13 | KR1: =Inputs!$D$13 | KS1: =Inputs!$E$13 | KU1: =Inputs!$D$13 | KV1: =Inputs!$E$13 | KX1: =Inputs!$D$13 | KY1: =Inputs!$E$13 | LA1: =Inputs!$D$13 | LB1: =Inputs!$E$13 | LD1: =Inputs!$D$13 | LE1: =Inputs!$E$13 | LG1: =Inputs!$D$13 | LH1: =Inputs!$E$13 | LJ1: =Inputs!$D$13 | LK1: =Inputs!$E$13 | LM1: =Inputs!$D$13 | LN1: =Inputs!$E$13 | LP1: =Inputs!$D$13 | LQ1: =Inputs!$E$13 | LS1: =Inputs!$D$13 | LT1: =Inputs!$E$13 | LV1: =Inputs!$D$13 | LW1: =Inputs!$E$13 | LY1: =Inputs!$D$13 | LZ1: =Inputs!$E$13 | MB1: =Inputs!$D$13 | MC1: =Inputs!$E$13 | ME1: =Inputs!$D$13 | MF1: =Inputs!$E$13 | MH1: =Inputs!$D$13 | MI1: =Inputs!$E$13 | MK1: =Inputs!$D$13 | ML1: =Inputs!$E$13 | MN1: =Inputs!$D$13 | MO1: =Inputs!$E$13 | MQ1: =Inputs!$D$13 | MR1: =Inputs!$E$13 | MT1: =Inputs!$D$13 | MU1: =Inputs!$E$13 | MW1: =Inputs!$D$13 | MX1: =Inputs!$E$13 | MZ1: =Inputs!$D$13 | NA1: =Inputs!$E$13 | NC1: =Inputs!$D$13 | ND1: =Inputs!$E$13 | NF1: =Inputs!$D$13 | NG1: =Inputs!$E$13 | NI1: =Inputs!$D$13 | NJ1: =Inputs!$E$13 | NL1: =Inputs!$D$13 | NM1: =Inputs!$E$13 | NO1: =Inputs!$D$13 | NP1: =Inputs!$E$13 | NR1: =Inputs!$D$13 | NS1: =Inputs!$E$13 | NU1: =Inputs!$D$13 | NV1: =Inputs!$E$13 | NX1: =Inputs!$D$13 | NY1: =Inputs!$E$13 | OA1: =Inputs!$D$13 | OB1: =Inputs!$E$13 | OD1: =Inputs!$D$13 | OE1: =Inputs!$E$13 | OG1: =Inputs!$D$13 | OH1: =Inputs!$E$13 | OJ1: =Inputs!$D$13 | OK1: =Inputs!$E$13 | OM1: =Inputs!$D$13 | ON1: =Inputs!$E$13 | OP1: =Inputs!$D$13 | OQ1: =Inputs!$E$13 | OS1: =Inputs!$D$13 | OT1: =Inputs!$E$13 | OV1: =Inputs!$D$13 | OW1: =Inputs!$E$13 | OY1: =Inputs!$D$13 | OZ1: =Inputs!$E$13 | PB1: =Inputs!$D$13 | PC1: =Inputs!$E$13 | PE1: =Inputs!$D$13 | PF1: =Inputs!$E$13 | PH1: =Inputs!$D$13 | PI1: =Inputs!$E$13 | PK1: =Inputs!$D$13 | PL1: =Inputs!$E$13 | PN1: =Inputs!$D$13 | PO1: =Inputs!$E$13 | PQ1: =Inputs!$D$14 | PR1: =Inputs!$E$14 | PT1: =Inputs!$D$14 | PU1: =Inputs!$E$14 | PW1: =Inputs!$D$14 | PX1: =Inputs!$E$14 | PZ1: =Inputs!$D$14 | QA1: =Inputs!$E$14 | QC1: =Inputs!$D$14 | QD1: =Inputs!$E$14 | QF1: =Inputs!$D$14 | QG1: =Inputs!$E$14 | QI1: =Inputs!$D$14 | QJ1: =Inputs!$E$14 | QL1: =Inputs!$D$14 | QM1: =Inputs!$E$14 | QO1: =Inputs!$D$14 | QP1: =Inputs!$E$14 | QR1: =Inputs!$D$14 | QS1: =Inputs!$E$14 | QU1: =Inputs!$D$14 | QV1: =Inputs!$E$14 | QX1: =Inputs!$D$14 | QY1: =Inputs!$E$14 | RA1: =Inputs!$D$14 | RB1: =Inputs!$E$14 | RD1: =Inputs!$D$14 | RE1: =Inputs!$E$14 | RG1: =Inputs!$D$14 | RH1: =Inputs!$E$14 | RJ1: =Inputs!$D$14 | RK1: =Inputs!$E$14 | RM1: =Inputs!$D$14 | RN1: =Inputs!$E$14 | RP1: =Inputs!$D$14 | RQ1: =Inputs!$E$14 | RS1: =Inputs!$D$14 | RT1: =Inputs!$E$14 | RV1: =Inputs!$D$14 | RW1: =Inputs!$E$14 | RY1: =Inputs!$D$14 | RZ1: =Inputs!$E$14 | SB1: =Inputs!$D$14 | SC1: =Inputs!$E$14 | SE1: =Inputs!$D$14 | SF1: =Inputs!$E$14 | SH1: =Inputs!$D$14 | SI1: =Inputs!$E$14 | SK1: =Inputs!$D$14 | SL1: =Inputs!$E$14 | SN1: =Inputs!$D$14 | SO1: =Inputs!$E$14 | SQ1: =Inputs!$D$14 | SR1: =Inputs!$E$14 | ST1: =Inputs!$D$14 | SU1: =Inputs!$E$14 | SW1: =Inputs!$D$14 | SX1: =Inputs!$E$14 | SZ1: =Inputs!$D$14 | TA1: =Inputs!$E$14 | TC1: =Inputs!$D$14 | TD1: =Inputs!$E$14 | TF1: =Inputs!$D$14 | TG1: =Inputs!$E$14 | TI1: =Inputs!$D$14 | TJ1: =Inputs!$E$14 | TL1: =Inputs!$D$14 | TM1: =Inputs!$E$14 | TO1: =Inputs!$D$14 | TP1: =Inputs!$E$14 | TR1: =Inputs!$D$14 | TS1: =Inputs!$E$14 | TU1: =Inputs!$D$14 | TV1: =Inputs!$E$14 | TX1: =Inputs!$D$14 | TY1: =Inputs!$E$14 | UA1: =Inputs!$D$14 | UB1: =Inputs!$E$14 | UD1: =Inputs!$D$14 | UE1: =Inputs!$E$14 | UG1: =Inputs!$D$14 | UH1: =Inputs!$E$14 | UJ1: =Inputs!$D$14 | UK1: =Inputs!$E$14 | UM1: =Inputs!$D$14 | UN1: =Inputs!$E$14 | UP1: =Inputs!$D$14 | UQ1: =Inputs!$E$14 | US1: =Inputs!$D$14 | UT1: =Inputs!$E$14 | UV1: =Inputs!$D$14 | UW1: =Inputs!$E$14 | UY1: =Inputs!$D$14 | UZ1: =Inputs!$E$14 | VB1: =Inputs!$D$14 | VC1: =Inputs!$E$14 | VE1: =Inputs!$D$15 | VF1: =Inputs!$E$15 | VH1: =Inputs!$D$15 | VI1: =Inputs!$E$15 | VK1: =Inputs!$D$15 | VL1: =Inputs!$E$15 | VN1: =Inputs!$D$15 | VO1: =Inputs!$E$15 | VQ1: =Inputs!$D$15 | VR1: =Inputs!$E$15 | VT1: =Inputs!$D$15 | VU1: =Inputs!$E$15 | VW1: =Inputs!$D$15 | VX1: =Inputs!$E$15 | VZ1: =Inputs!$D$15 | WA1: =Inputs!$E$15 | WC1: =Inputs!$D$15 | WD1: =Inputs!$E$15 | WF1: =Inputs!$D$15 | WG1: =Inputs!$E$15 | WI1: =Inputs!$D$15 | WJ1: =Inputs!$E$15 | WL1: =Inputs!$D$15 | WM1: =Inputs!$E$15 | WO1: =Inputs!$D$15 | WP1: =Inputs!$E$15 | WR1: =Inputs!$D$15 | WS1: =Inputs!$E$15 | WU1: =Inputs!$D$15 | WV1: =Inputs!$E$15 | WX1: =Inputs!$D$15 | WY1: =Inputs!$E$15 | XA1: =Inputs!$D$15 | XB1: =Inputs!$E$15 | XD1: =Inputs!$D$15 | XE1: =Inputs!$E$15 | XG1: =Inputs!$D$15 | XH1: =Inputs!$E$15 | XJ1: =Inputs!$D$15 | XK1: =Inputs!$E$15 | XM1: =Inputs!$D$15 | XN1: =Inputs!$E$15 | XP1: =Inputs!$D$15 | XQ1: =Inputs!$E$15 | XS1: =Inputs!$D$15 | XT1: =Inputs!$E$15 | XV1: =Inputs!$D$15 | XW1: =Inputs!$E$15 | XY1: =Inputs!$D$15 | XZ1: =Inputs!$E$15 | YB1: =Inputs!$D$15 | YC1: =Inputs!$E$15 | YE1: =Inputs!$D$15 | YF1: =Inputs!$E$15 | YH1: =Inputs!$D$15 | YI1: =Inputs!$E$15 | YK1: =Inputs!$D$15 | YL1: =Inputs!$E$15 | YN1: =Inputs!$D$15 | YO1: =Inputs!$E$15 | YQ1: =Inputs!$D$15 | YR1: =Inputs!$E$15 | YT1: =Inputs!$D$15 | YU1: =Inputs!$E$15 | YW1: =Inputs!$D$15 | YX1: =Inputs!$E$15 | YZ1: =Inputs!$D$15 | ZA1: =Inputs!$E$15 | ZC1: =Inputs!$D$15 | ZD1: =Inputs!$E$15 | ZF1: =Inputs!$D$15 | ZG1: =Inputs!$E$15 | ZI1: =Inputs!$D$15 | ZJ1: =Inputs!$E$15 | ZL1: =Inputs!$D$15 | ZM1: =Inputs!$E$15 | ZO1: =Inputs!$D$15 | ZP1: =Inputs!$E$15 | ZR1: =Inputs!$D$15 | ZS1: =Inputs!$E$15 | ZU1: =Inputs!$D$15 | ZV1: =Inputs!$E$15 | ZX1: =Inputs!$D$15 | ZY1: =Inputs!$E$15 | AAA1: =Inputs!$D$15 | AAB1: =Inputs!$E$15 | AAD1: =Inputs!$D$15 | AAE1: =Inputs!$E$15 | AAG1: =Inputs!$D$15 | AAH1: =Inputs!$E$15 | AAJ1: =Inputs!$D$15 | AAK1: =Inputs!$E$15 | AAM1: =Inputs!$D$15 | AAN1: =Inputs!$E$15 | AAP1: =Inputs!$D$15 | AAQ1: =Inputs!$E$15 | AAS1: =Inputs!$D$16 | AAT1: =Inputs!$E$16 | AAV1: =Inputs!$D$16 | AAW1: =Inputs!$E$16 | AAY1: =Inputs!$D$16 | AAZ1: =Inputs!$E$16 | ABB1: =Inputs!$D$16 | ABC1: =Inputs!$E$16 | ABE1: =Inputs!$D$16 | ABF1: =Inputs!$E$16 | ABH1: =Inputs!$D$16 | ABI1: =Inputs!$E$16 | ABK1: =Inputs!$D$16 | ABL1: =Inputs!$E$16 | ABN1: =Inputs!$D$16 | ABO1: =Inputs!$E$16 | ABQ1: =Inputs!$D$16 | ABR1: =Inputs!$E$16 | ABT1: =Inputs!$D$16 | ABU1: =Inputs!$E$16 | ABW1: =Inputs!$D$16 | ABX1: =Inputs!$E$16 | ABZ1: =Inputs!$D$16 | ACA1: =Inputs!$E$16 | ACC1: =Inputs!$D$16 | ACD1: =Inputs!$E$16 | ACF1: =Inputs!$D$16 | ACG1: =Inputs!$E$16 | ACI1: =Inputs!$D$16 | ACJ1: =Inputs!$E$16 | ACL1: =Inputs!$D$16 | ACM1: =Inputs!$E$16 | ACO1: =Inputs!$D$16 | ACP1: =Inputs!$E$16 | ACR1: =Inputs!$D$16 | ACS1: =Inputs!$E$16 | ACU1: =Inputs!$D$16 | ACV1: =Inputs!$E$16 | ACX1: =Inputs!$D$16 | ACY1: =Inputs!$E$16 | ADA1: =Inputs!$D$16 | ADB1: =Inputs!$E$16 | ADD1: =Inputs!$D$16 | ADE1: =Inputs!$E$16 | ADG1: =Inputs!$D$16 | ADH1: =Inputs!$E$16 | ADJ1: =Inputs!$D$16 | ADK1: =Inputs!$E$16 | ADM1: =Inputs!$D$16 | ADN1: =Inputs!$E$16 | ADP1: =Inputs!$D$16 | ADQ1: =Inputs!$E$16 | ADS1: =Inputs!$D$16 | ADT1: =Inputs!$E$16 | ADV1: =Inputs!$D$16 | ADW1: =Inputs!$E$16 | ADY1: =Inputs!$D$16 | ADZ1: =Inputs!$E$16 | AEB1: =Inputs!$D$16 | AEC1: =Inputs!$E$16 | AEE1: =Inputs!$D$16 | AEF1: =Inputs!$E$16 | AEH1: =Inputs!$D$16 | AEI1: =Inputs!$E$16 | AEK1: =Inputs!$D$16 | AEL1: =Inputs!$E$16 | AEN1: =Inputs!$D$16 | AEO1: =Inputs!$E$16 | AEQ1: =Inputs!$D$16 | AER1: =Inputs!$E$16 | AET1: =Inputs!$D$16 | AEU1: =Inputs!$E$16 | AEW1: =Inputs!$D$16 | AEX1: =Inputs!$E$16 | AEZ1: =Inputs!$D$16 | AFA1: =Inputs!$E$16 | AFC1: =Inputs!$D$16 | AFD1: =Inputs!$E$16 | AFF1: =Inputs!$D$16 | AFG1: =Inputs!$E$16 | AFI1: =Inputs!$D$16 | AFJ1: =Inputs!$E$16 | AFL1: =Inputs!$D$16 | AFM1: =Inputs!$E$16 | AFO1: =Inputs!$D$16 | AFP1: =Inputs!$E$16 | AFR1: =Inputs!$D$16 | AFS1: =Inputs!$E$16 | AFU1: =Inputs!$D$16 | AFV1: =Inputs!$E$16 | AFX1: =Inputs!$D$16 | AFY1: =Inputs!$E$16 | AGA1: =Inputs!$D$16 | AGB1: =Inputs!$E$16 | AGD1: =Inputs!$D$16 | AGE1: =Inputs!$E$16
A2: =Inputs!$B$11 | D2: =Inputs!$B$12 | G2: =Inputs!$B$13 | J2: =Inputs!$B$14 | M2: =Inputs!$B$15 | P2: =Inputs!$B$16 | S2: =Inputs!$B$17 | V2: =Inputs!$B$18 | Y2: =Inputs!$B$19 | AB2: =Inputs!$B$20 | AE2: =Inputs!$B$21 | AH2: =Inputs!$B$22 | AK2: =Inputs!$B$23 | AN2: =Inputs!$B$24 | AQ2: =Inputs!$B$25 | AT2: =Inputs!$B$26 | AW2: =Inputs!$B$27 | AZ2: =Inputs!$B$28 | BC2: =Inputs!$B$29 | BF2: =Inputs!$B$30 | BI2: =Inputs!$B$31 | BL2: =Inputs!$B$32 | BO2: =Inputs!$B$33 | BR2: =Inputs!$B$34 | BU2: =Inputs!$B$35 | BX2: =Inputs!$B$36 | CA2: =Inputs!$B$37 | CD2: =Inputs!$B$38 | CG2: =Inputs!$B$39 | CJ2: =Inputs!$B$40 | CM2: =Inputs!$B$41 | CP2: =Inputs!$B$42 | CS2: =Inputs!$B$43 | CV2: =Inputs!$B$44 | CY2: =Inputs!$B$45 | DB2: =Inputs!$B$46 | DE2: =Inputs!$B$47 | DH2: =Inputs!$B$48 | DK2: =Inputs!$B$49 | DN2: =Inputs!$B$50 | DQ2: =Inputs!$B$51 | DT2: =Inputs!$B$52 | DW2: =Inputs!$B$53 | DZ2: =Inputs!$B$54 | EC2: =Inputs!$B$55 | EF2: =Inputs!$B$56 | EI2: =Inputs!$B$57 | EL2: =Inputs!$B$58 | EO2: =Inputs!$B$11 | ER2: =Inputs!$B$12 | EU2: =Inputs!$B$13 | EX2: =Inputs!$B$14 | FA2: =Inputs!$B$15 | FD2: =Inputs!$B$16 | FG2: =Inputs!$B$17 | FJ2: =Inputs!$B$18 | FM2: =Inputs!$B$19 | FP2: =Inputs!$B$20 | FS2: =Inputs!$B$21 | FV2: =Inputs!$B$22 | FY2: =Inputs!$B$23 | GB2: =Inputs!$B$24 | GE2: =Inputs!$B$25 | GH2: =Inputs!$B$26 | GK2: =Inputs!$B$27 | GN2: =Inputs!$B$28 | GQ2: =Inputs!$B$29 | GT2: =Inputs!$B$30 | GW2: =Inputs!$B$31 | GZ2: =Inputs!$B$32 | HC2: =Inputs!$B$33 | HF2: =Inputs!$B$34 | HI2: =Inputs!$B$35 | HL2: =Inputs!$B$36 | HO2: =Inputs!$B$37 | HR2: =Inputs!$B$38 | HU2: =Inputs!$B$39 | HX2: =Inputs!$B$40 | IA2: =Inputs!$B$41 | ID2: =Inputs!$B$42 | IG2: =Inputs!$B$43 | IJ2: =Inputs!$B$44 | IM2: =Inputs!$B$45 | IP2: =Inputs!$B$46 | IS2: =Inputs!$B$47 | IV2: =Inputs!$B$48 | IY2: =Inputs!$B$49 | JB2: =Inputs!$B$50 | JE2: =Inputs!$B$51 | JH2: =Inputs!$B$52 | JK2: =Inputs!$B$53 | JN2: =Inputs!$B$54 | JQ2: =Inputs!$B$55 | JT2: =Inputs!$B$56 | JW2: =Inputs!$B$57 | JZ2: =Inputs!$B$58 | KC2: =Inputs!$B$11 | KF2: =Inputs!$B$12 | KI2: =Inputs!$B$13 | KL2: =Inputs!$B$14 | KO2: =Inputs!$B$15 | KR2: =Inputs!$B$16 | KU2: =Inputs!$B$17 | KX2: =Inputs!$B$18 | LA2: =Inputs!$B$19 | LD2: =Inputs!$B$20 | LG2: =Inputs!$B$21 | LJ2: =Inputs!$B$22 | LM2: =Inputs!$B$23 | LP2: =Inputs!$B$24 | LS2: =Inputs!$B$25 | LV2: =Inputs!$B$26 | LY2: =Inputs!$B$27 | MB2: =Inputs!$B$28 | ME2: =Inputs!$B$29 | MH2: =Inputs!$B$30 | MK2: =Inputs!$B$31 | MN2: =Inputs!$B$32 | MQ2: =Inputs!$B$33 | MT2: =Inputs!$B$34 | MW2: =Inputs!$B$35 | MZ2: =Inputs!$B$36 | NC2: =Inputs!$B$37 | NF2: =Inputs!$B$38 | NI2: =Inputs!$B$39 | NL2: =Inputs!$B$40 | NO2: =Inputs!$B$41 | NR2: =Inputs!$B$42 | NU2: =Inputs!$B$43 | NX2: =Inputs!$B$44 | OA2: =Inputs!$B$45 | OD2: =Inputs!$B$46 | OG2: =Inputs!$B$47 | OJ2: =Inputs!$B$48 | OM2: =Inputs!$B$49 | OP2: =Inputs!$B$50 | OS2: =Inputs!$B$51 | OV2: =Inputs!$B$52 | OY2: =Inputs!$B$53 | PB2: =Inputs!$B$54 | PE2: =Inputs!$B$55 | PH2: =Inputs!$B$56 | PK2: =Inputs!$B$57 | PN2: =Inputs!$B$58 | PQ2: =Inputs!$B$11 | PT2: =Inputs!$B$12 | PW2: =Inputs!$B$13 | PZ2: =Inputs!$B$14 | QC2: =Inputs!$B$15 | QF2: =Inputs!$B$16 | QI2: =Inputs!$B$17 | QL2: =Inputs!$B$18 | QO2: =Inputs!$B$19 | QR2: =Inputs!$B$20 | QU2: =Inputs!$B$21 | QX2: =Inputs!$B$22 | RA2: =Inputs!$B$23 | RD2: =Inputs!$B$24 | RG2: =Inputs!$B$25 | RJ2: =Inputs!$B$26 | RM2: =Inputs!$B$27 | RP2: =Inputs!$B$28 | RS2: =Inputs!$B$29 | RV2: =Inputs!$B$30 | RY2: =Inputs!$B$31 | SB2: =Inputs!$B$32 | SE2: =Inputs!$B$33 | SH2: =Inputs!$B$34 | SK2: =Inputs!$B$35 | SN2: =Inputs!$B$36 | SQ2: =Inputs!$B$37 | ST2: =Inputs!$B$38 | SW2: =Inputs!$B$39 | SZ2: =Inputs!$B$40 | TC2: =Inputs!$B$41 | TF2: =Inputs!$B$42 | TI2: =Inputs!$B$43 | TL2: =Inputs!$B$44 | TO2: =Inputs!$B$45 | TR2: =Inputs!$B$46 | TU2: =Inputs!$B$47 | TX2: =Inputs!$B$48 | UA2: =Inputs!$B$49 | UD2: =Inputs!$B$50 | UG2: =Inputs!$B$51 | UJ2: =Inputs!$B$52 | UM2: =Inputs!$B$53 | UP2: =Inputs!$B$54 | US2: =Inputs!$B$55 | UV2: =Inputs!$B$56 | UY2: =Inputs!$B$57 | VB2: =Inputs!$B$58 | VE2: =Inputs!$B$11 | VH2: =Inputs!$B$12 | VK2: =Inputs!$B$13 | VN2: =Inputs!$B$14 | VQ2: =Inputs!$B$15 | VT2: =Inputs!$B$16 | VW2: =Inputs!$B$17 | VZ2: =Inputs!$B$18 | WC2: =Inputs!$B$19 | WF2: =Inputs!$B$20 | WI2: =Inputs!$B$21 | WL2: =Inputs!$B$22 | WO2: =Inputs!$B$23 | WR2: =Inputs!$B$24 | WU2: =Inputs!$B$25 | WX2: =Inputs!$B$26 | XA2: =Inputs!$B$27 | XD2: =Inputs!$B$28 | XG2: =Inputs!$B$29 | XJ2: =Inputs!$B$30 | XM2: =Inputs!$B$31 | XP2: =Inputs!$B$32 | XS2: =Inputs!$B$33 | XV2: =Inputs!$B$34 | XY2: =Inputs!$B$35 | YB2: =Inputs!$B$36 | YE2: =Inputs!$B$37 | YH2: =Inputs!$B$38 | YK2: =Inputs!$B$39 | YN2: =Inputs!$B$40 | YQ2: =Inputs!$B$41 | YT2: =Inputs!$B$42 | YW2: =Inputs!$B$43 | YZ2: =Inputs!$B$44 | ZC2: =Inputs!$B$45 | ZF2: =Inputs!$B$46 | ZI2: =Inputs!$B$47 | ZL2: =Inputs!$B$48 | ZO2: =Inputs!$B$49 | ZR2: =Inputs!$B$50 | ZU2: =Inputs!$B$51 | ZX2: =Inputs!$B$52 | AAA2: =Inputs!$B$53 | AAD2: =Inputs!$B$54 | AAG2: =Inputs!$B$55 | AAJ2: =Inputs!$B$56 | AAM2: =Inputs!$B$57 | AAP2: =Inputs!$B$58 | AAS2: =Inputs!$B$11 | AAV2: =Inputs!$B$12 | AAY2: =Inputs!$B$13 | ABB2: =Inputs!$B$14 | ABE2: =Inputs!$B$15 | ABH2: =Inputs!$B$16 | ABK2: =Inputs!$B$17 | ABN2: =Inputs!$B$18 | ABQ2: =Inputs!$B$19 | ABT2: =Inputs!$B$20 | ABW2: =Inputs!$B$21 | ABZ2: =Inputs!$B$22 | ACC2: =Inputs!$B$23 | ACF2: =Inputs!$B$24 | ACI2: =Inputs!$B$25 | ACL2: =Inputs!$B$26 | ACO2: =Inputs!$B$27 | ACR2: =Inputs!$B$28 | ACU2: =Inputs!$B$29 | ACX2: =Inputs!$B$30 | ADA2: =Inputs!$B$31 | ADD2: =Inputs!$B$32 | ADG2: =Inputs!$B$33 | ADJ2: =Inputs!$B$34 | ADM2: =Inputs!$B$35 | ADP2: =Inputs!$B$36 | ADS2: =Inputs!$B$37 | ADV2: =Inputs!$B$38 | ADY2: =Inputs!$B$39 | AEB2: =Inputs!$B$40 | AEE2: =Inputs!$B$41 | AEH2: =Inputs!$B$42 | AEK2: =Inputs!$B$43 | AEN2: =Inputs!$B$44 | AEQ2: =Inputs!$B$45 | AET2: =Inputs!$B$46 | AEW2: =Inputs!$B$47 | AEZ2: =Inputs!$B$48 | AFC2: =Inputs!$B$49 | AFF2: =Inputs!$B$50 | AFI2: =Inputs!$B$51 | AFL2: =Inputs!$B$52 | AFO2: =Inputs!$B$53 | AFR2: =Inputs!$B$54 | AFU2: =Inputs!$B$55 | AFX2: =Inputs!$B$56 | AGA2: =Inputs!$B$57 | AGD2: =Inputs!$B$58
A3: Member | B3: Weight | D3: Member | E3: Weight | G3: Member | H3: Weight | J3: Member | K3: Weight | M3: Member | N3: Weight | P3: Member | Q3: Weight | S3: Member | T3: Weight | V3: Member | W3: Weight | Y3: Member | Z3: Weight | AB3: Member | AC3: Weight | AE3: Member | AF3: Weight | AH3: Member | AI3: Weight | AK3: Member | AL3: Weight | AN3: Member | AO3: Weight | AQ3: Member | AR3: Weight | AT3: Member | AU3: Weight | AW3: Member | AX3: Weight | AZ3: Member | BA3: Weight | BC3: Member | BD3: Weight | BF3: Member | BG3: Weight | BI3: Member | BJ3: Weight | BL3: Member | BM3: Weight | BO3: Member | BP3: Weight | BR3: Member | BS3: Weight | BU3: Member | BV3: Weight | BX3: Member | BY3: Weight | CA3: Member | CB3: Weight | CD3: Member | CE3: Weight | CG3: Member | CH3: Weight | CJ3: Member | CK3: Weight | CM3: Member | CN3: Weight | CP3: Member | CQ3: Weight | CS3: Member | CT3: Weight | CV3: Member | CW3: Weight | CY3: Member | CZ3: Weight | DB3: Member | DC3: Weight | DE3: Member | DF3: Weight | DH3: Member | DI3: Weight | DK3: Member | DL3: Weight | DN3: Member | DO3: Weight | DQ3: Member | DR3: Weight | DT3: Member | DU3: Weight | DW3: Member | DX3: Weight | DZ3: Member | EA3: Weight | EC3: Member | ED3: Weight | EF3: Member | EG3: Weight | EI3: Member | EJ3: Weight | EL3: Member | EM3: Weight | EO3: Member | EP3: Weight | ER3: Member | ES3: Weight | EU3: Member | EV3: Weight | EX3: Member | EY3: Weight | FA3: Member | FB3: Weight | FD3: Member | FE3: Weight | FG3: Member | FH3: Weight | FJ3: Member | FK3: Weight | FM3: Member | FN3: Weight | FP3: Member | FQ3: Weight | FS3: Member | FT3: Weight | FV3: Member | FW3: Weight | FY3: Member | FZ3: Weight | GB3: Member | GC3: Weight | GE3: Member | GF3: Weight | GH3: Member | GI3: Weight | GK3: Member | GL3: Weight | GN3: Member | GO3: Weight | GQ3: Member | GR3: Weight | GT3: Member | GU3: Weight | GW3: Member | GX3: Weight | GZ3: Member | HA3: Weight | HC3: Member | HD3: Weight | HF3: Member | HG3: Weight | HI3: Member | HJ3: Weight | HL3: Member | HM3: Weight | HO3: Member | HP3: Weight | HR3: Member | HS3: Weight | HU3: Member | HV3: Weight | HX3: Member | HY3: Weight | IA3: Member | IB3: Weight | ID3: Member | IE3: Weight | IG3: Member | IH3: Weight | IJ3: Member | IK3: Weight | IM3: Member | IN3: Weight | IP3: Member | IQ3: Weight | IS3: Member | IT3: Weight | IV3: Member | IW3: Weight | IY3: Member | IZ3: Weight | JB3: Member | JC3: Weight | JE3: Member | JF3: Weight | JH3: Member | JI3: Weight | JK3: Member | JL3: Weight | JN3: Member | JO3: Weight | JQ3: Member | JR3: Weight | JT3: Member | JU3: Weight | JW3: Member | JX3: Weight | JZ3: Member | KA3: Weight | KC3: Member | KD3: Weight | KF3: Member | KG3: Weight | KI3: Member | KJ3: Weight | KL3: Member | KM3: Weight | KO3: Member | KP3: Weight | KR3: Member | KS3: Weight | KU3: Member | KV3: Weight | KX3: Member | KY3: Weight | LA3: Member | LB3: Weight | LD3: Member | LE3: Weight | LG3: Member | LH3: Weight | LJ3: Member | LK3: Weight | LM3: Member | LN3: Weight | LP3: Member | LQ3: Weight | LS3: Member | LT3: Weight | LV3: Member | LW3: Weight | LY3: Member | LZ3: Weight | MB3: Member | MC3: Weight | ME3: Member | MF3: Weight | MH3: Member | MI3: Weight | MK3: Member | ML3: Weight | MN3: Member | MO3: Weight | MQ3: Member | MR3: Weight | MT3: Member | MU3: Weight | MW3: Member | MX3: Weight | MZ3: Member | NA3: Weight | NC3: Member | ND3: Weight | NF3: Member | NG3: Weight | NI3: Member | NJ3: Weight | NL3: Member | NM3: Weight | NO3: Member | NP3: Weight | NR3: Member | NS3: Weight | NU3: Member | NV3: Weight | NX3: Member | NY3: Weight | OA3: Member | OB3: Weight | OD3: Member | OE3: Weight | OG3: Member | OH3: Weight | OJ3: Member | OK3: Weight | OM3: Member | ON3: Weight | OP3: Member | OQ3: Weight | OS3: Member | OT3: Weight | OV3: Member | OW3: Weight | OY3: Member | OZ3: Weight | PB3: Member | PC3: Weight | PE3: Member | PF3: Weight | PH3: Member | PI3: Weight | PK3: Member | PL3: Weight | PN3: Member | PO3: Weight | PQ3: Member | PR3: Weight | PT3: Member | PU3: Weight | PW3: Member | PX3: Weight | PZ3: Member | QA3: Weight | QC3: Member | QD3: Weight | QF3: Member | QG3: Weight | QI3: Member | QJ3: Weight | QL3: Member | QM3: Weight | QO3: Member | QP3: Weight | QR3: Member | QS3: Weight | QU3: Member | QV3: Weight | QX3: Member | QY3: Weight | RA3: Member | RB3: Weight | RD3: Member | RE3: Weight | RG3: Member | RH3: Weight | RJ3: Member | RK3: Weight | RM3: Member | RN3: Weight | RP3: Member | RQ3: Weight | RS3: Member | RT3: Weight | RV3: Member | RW3: Weight | RY3: Member | RZ3: Weight | SB3: Member | SC3: Weight | SE3: Member | SF3: Weight | SH3: Member | SI3: Weight | SK3: Member | SL3: Weight | SN3: Member | SO3: Weight | SQ3: Member | SR3: Weight | ST3: Member | SU3: Weight | SW3: Member | SX3: Weight | SZ3: Member | TA3: Weight | TC3: Member | TD3: Weight | TF3: Member | TG3: Weight | TI3: Member | TJ3: Weight | TL3: Member | TM3: Weight | TO3: Member | TP3: Weight | TR3: Member | TS3: Weight | TU3: Member | TV3: Weight | TX3: Member | TY3: Weight | UA3: Member | UB3: Weight | UD3: Member | UE3: Weight | UG3: Member | UH3: Weight | UJ3: Member | UK3: Weight | UM3: Member | UN3: Weight | UP3: Member | UQ3: Weight | US3: Member | UT3: Weight | UV3: Member | UW3: Weight | UY3: Member | UZ3: Weight | VB3: Member | VC3: Weight | VE3: Member | VF3: Weight | VH3: Member | VI3: Weight | VK3: Member | VL3: Weight | VN3: Member | VO3: Weight | VQ3: Member | VR3: Weight | VT3: Member | VU3: Weight | VW3: Member | VX3: Weight | VZ3: Member | WA3: Weight | WC3: Member | WD3: Weight | WF3: Member | WG3: Weight | WI3: Member | WJ3: Weight | WL3: Member | WM3: Weight | WO3: Member | WP3: Weight | WR3: Member | WS3: Weight | WU3: Member | WV3: Weight | WX3: Member | WY3: Weight | XA3: Member | XB3: Weight | XD3: Member | XE3: Weight | XG3: Member | XH3: Weight | XJ3: Member | XK3: Weight | XM3: Member | XN3: Weight | XP3: Member | XQ3: Weight | XS3: Member | XT3: Weight | XV3: Member | XW3: Weight | XY3: Member | XZ3: Weight | YB3: Member | YC3: Weight | YE3: Member | YF3: Weight | YH3: Member | YI3: Weight | YK3: Member | YL3: Weight | YN3: Member | YO3: Weight | YQ3: Member | YR3: Weight | YT3: Member | YU3: Weight | YW3: Member | YX3: Weight | YZ3: Member | ZA3: Weight | ZC3: Member | ZD3: Weight | ZF3: Member | ZG3: Weight | ZI3: Member | ZJ3: Weight | ZL3: Member | ZM3: Weight | ZO3: Member | ZP3: Weight | ZR3: Member | ZS3: Weight | ZU3: Member | ZV3: Weight | ZX3: Member | ZY3: Weight | AAA3: Member | AAB3: Weight | AAD3: Member | AAE3: Weight | AAG3: Member | AAH3: Weight | AAJ3: Member | AAK3: Weight | AAM3: Member | AAN3: Weight | AAP3: Member | AAQ3: Weight | AAS3: Member | AAT3: Weight | AAV3: Member | AAW3: Weight | AAY3: Member | AAZ3: Weight | ABB3: Member | ABC3: Weight | ABE3: Member | ABF3: Weight | ABH3: Member | ABI3: Weight | ABK3: Member | ABL3: Weight | ABN3: Member | ABO3: Weight | ABQ3: Member | ABR3: Weight | ABT3: Member | ABU3: Weight | ABW3: Member | ABX3: Weight | ABZ3: Member | ACA3: Weight | ACC3: Member | ACD3: Weight | ACF3: Member | ACG3: Weight | ACI3: Member | ACJ3: Weight | ACL3: Member | ACM3: Weight | ACO3: Member | ACP3: Weight | ACR3: Member | ACS3: Weight | ACU3: Member | ACV3: Weight | ACX3: Member | ACY3: Weight | ADA3: Member | ADB3: Weight | ADD3: Member | ADE3: Weight | ADG3: Member | ADH3: Weight | ADJ3: Member | ADK3: Weight | ADM3: Member | ADN3: Weight | ADP3: Member | ADQ3: Weight | ADS3: Member | ADT3: Weight | ADV3: Member | ADW3: Weight | ADY3: Member | ADZ3: Weight | AEB3: Member | AEC3: Weight | AEE3: Member | AEF3: Weight | AEH3: Member | AEI3: Weight | AEK3: Member | AEL3: Weight | AEN3: Member | AEO3: Weight | AEQ3: Member | AER3: Weight | AET3: Member | AEU3: Weight | AEW3: Member | AEX3: Weight | AEZ3: Member | AFA3: Weight | AFC3: Member | AFD3: Weight | AFF3: Member | AFG3: Weight | AFI3: Member | AFJ3: Weight | AFL3: Member | AFM3: Weight | AFO3: Member | AFP3: Weight | AFR3: Member | AFS3: Weight | AFU3: Member | AFV3: Weight | AFX3: Member | AFY3: Weight | AGA3: Member | AGB3: Weight | AGD3: Member | AGE3: Weight
